[2023-02-24 21:30:07,290] {taskinstance.py:1159} INFO - Dependencies all met for <TaskInstance: aws_extract_dag.aws_task_powered_by_airflow manual__2023-02-24T21:29:17.970700+00:00 [queued]>
[2023-02-24 21:30:07,300] {taskinstance.py:1159} INFO - Dependencies all met for <TaskInstance: aws_extract_dag.aws_task_powered_by_airflow manual__2023-02-24T21:29:17.970700+00:00 [queued]>
[2023-02-24 21:30:07,301] {taskinstance.py:1356} INFO - 
--------------------------------------------------------------------------------
[2023-02-24 21:30:07,302] {taskinstance.py:1357} INFO - Starting attempt 1 of 1
[2023-02-24 21:30:07,302] {taskinstance.py:1358} INFO - 
--------------------------------------------------------------------------------
[2023-02-24 21:30:07,323] {taskinstance.py:1377} INFO - Executing <Task(PythonOperator): aws_task_powered_by_airflow> on 2023-02-24 21:29:17.970700+00:00
[2023-02-24 21:30:07,350] {standard_task_runner.py:52} INFO - Started process 964 to run task
[2023-02-24 21:30:07,360] {standard_task_runner.py:79} INFO - Running: ['***', 'tasks', 'run', 'aws_extract_dag', 'aws_task_powered_by_***', 'manual__2023-02-24T21:29:17.970700+00:00', '--job-id', '42', '--raw', '--subdir', 'DAGS_FOLDER/aws_dag.py', '--cfg-path', '/tmp/tmpb6u2glks', '--error-file', '/tmp/tmpqtko3boo']
[2023-02-24 21:30:07,362] {standard_task_runner.py:80} INFO - Job 42: Subtask aws_task_powered_by_***
[2023-02-24 21:30:07,444] {task_command.py:369} INFO - Running <TaskInstance: aws_extract_dag.aws_task_powered_by_airflow manual__2023-02-24T21:29:17.970700+00:00 [running]> on host b3a66ff5f0fe
[2023-02-24 21:30:07,559] {taskinstance.py:1571} INFO - Exporting the following env vars:
AIRFLOW_CTX_DAG_OWNER=***
AIRFLOW_CTX_DAG_ID=aws_extract_dag
AIRFLOW_CTX_TASK_ID=aws_task_powered_by_***
AIRFLOW_CTX_EXECUTION_DATE=2023-02-24T21:29:17.970700+00:00
AIRFLOW_CTX_TRY_NUMBER=1
AIRFLOW_CTX_DAG_RUN_ID=manual__2023-02-24T21:29:17.970700+00:00
[2023-02-24 21:30:07,577] {taskinstance.py:1889} ERROR - Task failed with exception
Traceback (most recent call last):
  File "/home/airflow/.local/lib/python3.7/site-packages/airflow/operators/python.py", line 171, in execute
    return_value = self.execute_callable()
  File "/home/airflow/.local/lib/python3.7/site-packages/airflow/operators/python.py", line 189, in execute_callable
    return self.python_callable(*self.op_args, **self.op_kwargs)
  File "/opt/airflow/plugins/sql_aws_metadata.py", line 167, in aws_extract_data_to_sqlite
    metadata_instance = Metadata()
  File "/opt/airflow/plugins/sql_aws_metadata.py", line 74, in __init__
    self.conn = sql.connect(self.database_name)
sqlite3.OperationalError: unable to open database file
[2023-02-24 21:30:07,614] {taskinstance.py:1400} INFO - Marking task as FAILED. dag_id=aws_extract_dag, task_id=aws_task_powered_by_***, execution_date=20230224T212917, start_date=20230224T213007, end_date=20230224T213007
[2023-02-24 21:30:07,638] {standard_task_runner.py:97} ERROR - Failed to execute job 42 for task aws_task_powered_by_*** (unable to open database file; 964)
[2023-02-24 21:30:07,694] {local_task_job.py:156} INFO - Task exited with return code 1
[2023-02-24 21:30:07,809] {local_task_job.py:273} INFO - 0 downstream tasks scheduled from follow-on schedule check
